2024-03-11 10:10:20,318 INFO    StreamThr :19116 [internal.py:wandb_internal():86] W&B internal server running at pid: 19116, started at: 2024-03-11 10:10:20.317552
2024-03-11 10:10:20,320 DEBUG   HandlerThread:19116 [handler.py:handle_request():146] handle_request: status
2024-03-11 10:10:20,325 INFO    WriterThread:19116 [datastore.py:open_for_write():87] open: C:\Users\yyyfa\ConstrainedDGM\wandb\run-20240311_101020-unconstrained_random_0_adam_300_128_100_64_11-03-24--10-06-28\run-unconstrained_random_0_adam_300_128_100_64_11-03-24--10-06-28.wandb
2024-03-11 10:10:20,326 DEBUG   SenderThread:19116 [sender.py:send():378] send: header
2024-03-11 10:10:20,408 DEBUG   SenderThread:19116 [sender.py:send():378] send: run
2024-03-11 10:10:20,968 ERROR   SenderThread:19116 [internal_api.py:execute():373] 401 response executing GraphQL.
2024-03-11 10:10:20,968 ERROR   SenderThread:19116 [internal_api.py:execute():374] {"errors":[{"message":"user is not logged in","path":["upsertBucket"],"extensions":{"code":"PERMISSION_ERROR"}}],"data":{"upsertBucket":null}}
2024-03-11 10:10:20,982 ERROR   SenderThread:19116 [sender.py:send_run():950] The API key you provided is either invalid or missing.  If the `WANDB_API_KEY` environment variable is set, make sure it is correct. Otherwise, to resolve this issue, you may try running the 'wandb login --relogin' command. If you are using a local server, make sure that you're using the correct hostname. If you're not sure, you can try logging in again using the 'wandb login --relogin --host [hostname]' command.(Error 401: Unauthorized)
Traceback (most recent call last):
  File "D:\Python\envs\cdgm\lib\site-packages\wandb\sdk\lib\retry.py", line 131, in __call__
    result = self._call_fn(*args, **kwargs)
  File "D:\Python\envs\cdgm\lib\site-packages\wandb\sdk\internal\internal_api.py", line 369, in execute
    return self.client.execute(*args, **kwargs)  # type: ignore
  File "D:\Python\envs\cdgm\lib\site-packages\wandb\vendor\gql-0.2.0\wandb_gql\client.py", line 52, in execute
    result = self._get_result(document, *args, **kwargs)
  File "D:\Python\envs\cdgm\lib\site-packages\wandb\vendor\gql-0.2.0\wandb_gql\client.py", line 60, in _get_result
    return self.transport.execute(document, *args, **kwargs)
  File "D:\Python\envs\cdgm\lib\site-packages\wandb\sdk\lib\gql_request.py", line 59, in execute
    request.raise_for_status()
  File "D:\Python\envs\cdgm\lib\site-packages\requests\models.py", line 1021, in raise_for_status
    raise HTTPError(http_error_msg, response=self)
requests.exceptions.HTTPError: 401 Client Error: Unauthorized for url: https://api.wandb.ai/graphql

During handling of the above exception, another exception occurred:

Traceback (most recent call last):
  File "D:\Python\envs\cdgm\lib\site-packages\wandb\sdk\internal\sender.py", line 948, in send_run
    self._init_run(run, config_value_dict)
  File "D:\Python\envs\cdgm\lib\site-packages\wandb\sdk\internal\sender.py", line 990, in _init_run
    server_run, inserted, server_messages = self._api.upsert_run(
  File "D:\Python\envs\cdgm\lib\site-packages\wandb\apis\normalize.py", line 73, in wrapper
    raise err
  File "D:\Python\envs\cdgm\lib\site-packages\wandb\apis\normalize.py", line 41, in wrapper
    return func(*args, **kwargs)
  File "D:\Python\envs\cdgm\lib\site-packages\wandb\sdk\internal\internal_api.py", line 2216, in upsert_run
    response = self.gql(
  File "D:\Python\envs\cdgm\lib\site-packages\wandb\sdk\internal\internal_api.py", line 341, in gql
    ret = self._retry_gql(
  File "D:\Python\envs\cdgm\lib\site-packages\wandb\sdk\lib\retry.py", line 147, in __call__
    retry_timedelta_triggered = check_retry_fn(e)
  File "D:\Python\envs\cdgm\lib\site-packages\wandb\util.py", line 968, in check_retry_fn
    return fallback_retry_fn(e)
  File "D:\Python\envs\cdgm\lib\site-packages\wandb\util.py", line 899, in no_retry_auth
    raise AuthenticationError(
wandb.errors.AuthenticationError: The API key you provided is either invalid or missing.  If the `WANDB_API_KEY` environment variable is set, make sure it is correct. Otherwise, to resolve this issue, you may try running the 'wandb login --relogin' command. If you are using a local server, make sure that you're using the correct hostname. If you're not sure, you can try logging in again using the 'wandb login --relogin --host [hostname]' command.(Error 401: Unauthorized)
2024-03-11 10:10:21,375 DEBUG   HandlerThread:19116 [handler.py:handle_request():146] handle_request: shutdown
2024-03-11 10:10:21,375 INFO    HandlerThread:19116 [handler.py:finish():869] shutting down handler
2024-03-11 10:10:21,422 INFO    WriterThread:19116 [datastore.py:close():296] close: C:\Users\yyyfa\ConstrainedDGM\wandb\run-20240311_101020-unconstrained_random_0_adam_300_128_100_64_11-03-24--10-06-28\run-unconstrained_random_0_adam_300_128_100_64_11-03-24--10-06-28.wandb
2024-03-11 10:10:22,014 INFO    SenderThread:19116 [sender.py:finish():1521] shutting down sender
