Traceback (most recent call last):
  File "C:\Users\yyyfa\ConstrainedDGM\main_tableGAN.py", line 199, in <module>
    main()
  File "C:\Users\yyyfa\ConstrainedDGM\main_tableGAN.py", line 83, in main
    X_test = pd.read_csv(f"data/{args.use_case}/test_data.csv")
  File "D:\Python\envs\cdgm\lib\site-packages\pandas\util\_decorators.py", line 211, in wrapper
    return func(*args, **kwargs)
  File "D:\Python\envs\cdgm\lib\site-packages\pandas\util\_decorators.py", line 331, in wrapper
    return func(*args, **kwargs)
  File "D:\Python\envs\cdgm\lib\site-packages\pandas\io\parsers\readers.py", line 950, in read_csv
    return _read(filepath_or_buffer, kwds)
  File "D:\Python\envs\cdgm\lib\site-packages\pandas\io\parsers\readers.py", line 605, in _read
    parser = TextFileReader(filepath_or_buffer, **kwds)
  File "D:\Python\envs\cdgm\lib\site-packages\pandas\io\parsers\readers.py", line 1442, in __init__
    self._engine = self._make_engine(f, self.engine)
  File "D:\Python\envs\cdgm\lib\site-packages\pandas\io\parsers\readers.py", line 1735, in _make_engine
    self.handles = get_handle(
  File "D:\Python\envs\cdgm\lib\site-packages\pandas\io\common.py", line 856, in get_handle
    handle = open(
FileNotFoundError: [Errno 2] No such file or directory: 'data/faults/test_data.csv'
Traceback (most recent call last):
  File "C:\Users\yyyfa\ConstrainedDGM\main_tableGAN.py", line 199, in <module>
    main()
  File "C:\Users\yyyfa\ConstrainedDGM\main_tableGAN.py", line 83, in main
    X_test = pd.read_csv(f"data/{args.use_case}/test_data.csv")
  File "D:\Python\envs\cdgm\lib\site-packages\pandas\util\_decorators.py", line 211, in wrapper
    return func(*args, **kwargs)
  File "D:\Python\envs\cdgm\lib\site-packages\pandas\util\_decorators.py", line 331, in wrapper
    return func(*args, **kwargs)
  File "D:\Python\envs\cdgm\lib\site-packages\pandas\io\parsers\readers.py", line 950, in read_csv
    return _read(filepath_or_buffer, kwds)
  File "D:\Python\envs\cdgm\lib\site-packages\pandas\io\parsers\readers.py", line 605, in _read
    parser = TextFileReader(filepath_or_buffer, **kwds)
  File "D:\Python\envs\cdgm\lib\site-packages\pandas\io\parsers\readers.py", line 1442, in __init__
    self._engine = self._make_engine(f, self.engine)
  File "D:\Python\envs\cdgm\lib\site-packages\pandas\io\parsers\readers.py", line 1735, in _make_engine
    self.handles = get_handle(
  File "D:\Python\envs\cdgm\lib\site-packages\pandas\io\common.py", line 856, in get_handle
    handle = open(
FileNotFoundError: [Errno 2] No such file or directory: 'data/faults/test_data.csv'
{'problem_type': 'multiclass_classification', 'target_col': 'faults', 'target_size': 7, 'manual_inspection_categorical_cols_idx': [27], 'feats_in_constraints': [0, 1, 2, 3, 7, 8, 9]}